Workbook

Sheet Customers
A1: customer_id | B1: customer_name | C1: segment | D1: join_date | E1: region | F1: status
A2: CUST10000 | B2: Johnson, Olson and Smith | C2: Online | D2: 43918 | E2: North | F2: Active
A3: CUST10001 | B3: Colon-Valdez | C3: Enterprise | D3: 43146 | E3: West | F3: Active
A4: CUST10002 | B4: Henry, Jones and Farley | C4: Online | D4: 44641 | E4: North | F4: Active
A5: CUST10003 | B5: Williams-Dalton | C5: Retail | D5: 44277 | E5: West | F5: Active
A6: CUST10004 | B6: Fisher-Serrano | C6: Enterprise | D6: 43406 | E6: East | F6: Active
A7: CUST10005 | B7: Jennings Ltd | C7: Online | D7: 43663 | E7: South | F7: Active
A8: CUST10006 | B8: Tate-Haas | C8: Retail | D8: 45212 | E8: West | F8: Active
A9: CUST10007 | B9: Brooks, Aguilar and Young | C9: Enterprise | D9: 43234 | E9: North | F9: Active
A10: CUST10008 | B10: Herrera-Ingram | C10: Retail | D10: 43350 | E10: East | F10: Active
A11: CUST10009 | B11: Dunn, Graham and Brown | C11: Retail | D11: 44229 | E11: West | F11: Active
A12: CUST10010 | B12: Moore, Walker and Gutierrez | C12: Retail | D12: 42831 | E12: East | F12: Active
A13: CUST10011 | B13: Turner-Lawson | C13: Enterprise | D13: 42920 | E13: West | F13: Active
... A401: CUST10399 | B401: Marshall-Horne | C401: Enterprise | D401: 43563 | E401: East | F401: Inactive

Sheet Vendors
A1: vendor_id | B1: vendor_name | C1: category | D1: region | E1: active
A2: VEND1000 | B2: Johnson-Howard | C2: Supplies | D2: East | E2: Y
A3: VEND1001 | B3: Jensen Ltd | C3: Consulting | D3: South | E3: Y
A4: VEND1002 | B4: Collins Group | C4: Services | D4: North | E4: Y
A5: VEND1003 | B5: Smith, Kirby and Torres | C5: Utilities | D5: North | E5: Y
A6: VEND1004 | B6: Mcgrath, Wheeler and Boyd | C6: Utilities | D6: North | E6: Y
A7: VEND1005 | B7: Cooper-Larson | C7: Supplies | D7: South | E7: Y
A8: VEND1006 | B8: Ward-David | C8: Utilities | D8: South | E8: Y
A9: VEND1007 | B9: Savage Ltd | C9: Utilities | D9: West | E9: Y
A10: VEND1008 | B10: Medina-Lee | C10: Services | D10: South | E10: Y
A11: VEND1009 | B11: Griffith and Sons | C11: Services | D11: East | E11: Y
A12: VEND1010 | B12: Thomas-Santana | C12: Rent | D12: South | E12: Y
... A121: VEND1119 | B121: Graham-Lopez | C121: Consulting | D121: North | E121: N

Sheet Headcount
A1: employee_id | B1: employee_name | C1: business_unit | D1: join_date | E1: status | F1: region | G1: cost_to_company
A2: EMP1000 | B2: Daniel Thornton | C2: Enterprise | D2: 44968 | E2: Active | F2: South | G2: 1566441
A3: EMP1001 | B3: Ashley Burch | C3: Retail | D3: 44084 | E3: Active | F3: West | G3: 1533942
A4: EMP1002 | B4: Angel Perry | C4: Online | D4: 44620 | E4: Active | F4: East | G4: 962333
A5: EMP1003 | B5: Kimberly Harmon | C5: Online | D5: 44484 | E5: Active | F5: North | G5: 503403
A6: EMP1004 | B6: Sarah Smith DDS | C6: Enterprise | D6: 44957 | E6: Active | F6: West | G6: 1051271
A7: EMP1005 | B7: Sierra Jordan | C7: Enterprise | D7: 44945 | E7: Active | F7: South | G7: 731473
A8: EMP1006 | B8: Adam Wood | C8: Enterprise | D8: 43768 | E8: Active | F8: West | G8: 596883
A9: EMP1007 | B9: Keith Collins | C9: Online | D9: 44993 | E9: Active | F9: East | G9: 864597
A10: EMP1008 | B10: Mitchell Kelly | C10: Enterprise | D10: 44438 | E10: Active | F10: North | G10: 1736454
A11: EMP1009 | B11: Jacob Mendez | C11: Enterprise | D11: 45166 | E11: Active | F11: North | G11: 1479884
A12: EMP1010 | B12: William Bryant | C12: Enterprise | D12: 44563 | E12: Active | F12: North | G12: 1160373
A13: EMP1011 | B13: Sean Daniels | C13: Retail | D13: 44741 | E13: Active | F13: South | G13: 1603487
... A201: EMP1199 | B201: Mr. Alec Nelson | C201: Enterprise | D201: 44808 | E201: Inactive | F201: South | G201: 728593

Sheet Budget
A1: year | B1: month | C1: business_unit | D1: budgeted_revenue | E1: budgeted_expense
A2: 2022 | B2: 1 | C2: Retail | D2: 1530660 | E2: 1259760
A3: 2022 | B3: 1 | C3: Enterprise | D3: 1689240 | E3: 1152615
A4: 2022 | B4: 1 | C4: Online | D4: 2069088 | E4: 1776169
A5: 2022 | B5: 2 | C5: Retail | D5: 1836984 | E5: 1201730
A6: 2022 | B6: 2 | C6: Enterprise | D6: 1923012 | E6: 1454263
A7: 2022 | B7: 2 | C7: Online | D7: 1516272 | E7: 1117069
A8: 2022 | B8: 3 | C8: Retail | D8: 1510920 | E8: 1106833
A9: 2022 | B9: 3 | C9: Enterprise | D9: 1576692 | E9: 959653
A10: 2022 | B10: 3 | C10: Online | D10: 2119464 | E10: 1677676
A11: 2022 | B11: 4 | C11: Retail | D11: 1731204 | E11: 1275919
A12: 2022 | B12: 4 | C12: Enterprise | D12: 2042184 | E12: 1592655
A13: 2022 | B13: 4 | C13: Online | D13: 2132844 | E13: 1388082
... A73: 2023 | B73: 12 | C73: Online | D73: 2263008 | E73: 1662605

Sheet Financial_Transactions
A1: transaction_id | B1: transaction_date | C1: amount | D1: account_type | E1: category | F1: business_unit | G1: region | H1: customer_id | I1: vendor_id | J1: description | K1: customer_fk_check | L1: vendor_fk_check | M1: headcount_fk_check
A2: TRX100000 | B2: 45172 | C2: -66631.73 | D2: Expense | E2: Supplies | F2: Online | G2: West | I2: VEND1053 | J2: Begin catch control dark practice. | K2: =IF(ISNA(XLOOKUP(A2,Customers!A:A,Customers!A:A)),"Invalid FK","Valid") -> Valid | L2: =IF(ISNA(XLOOKUP(B2,Vendors!A:A,Vendors!A:A)),"Invalid FK","Valid") -> Valid | M2: =IF(ISNA(XLOOKUP(C2,Headcount!C:C,Headcount!C:C)),"Invalid FK","Valid") -> Valid
A3: TRX100001 | B3: 45182 | C3: -54305.58 | D3: Expense | E3: Utilities | F3: Enterprise | G3: East | I3: VEND1059 | J3: Style guy soldier boy energy above. | K3: =IF(ISNA(XLOOKUP(A3,Customers!A:A,Customers!A:A)),"Invalid FK","Valid") -> Valid | L3: =IF(ISNA(XLOOKUP(B3,Vendors!A:A,Vendors!A:A)),"Invalid FK","Valid") -> Valid | M3: =IF(ISNA(XLOOKUP(C3,Headcount!C:C,Headcount!C:C)),"Invalid FK","Valid") -> Valid
A4: TRX100002 | B4: 45104 | C4: 146074.92 | D4: Revenue | E4: Subscription | F4: Online | G4: East | H4: CUST10122 | J4: Skill surface drug personal western. | K4: =IF(ISNA(XLOOKUP(A4,Customers!A:A,Customers!A:A)),"Invalid FK","Valid") -> Valid | L4: =IF(ISNA(XLOOKUP(B4,Vendors!A:A,Vendors!A:A)),"Invalid FK","Valid") -> Valid | M4: =IF(ISNA(XLOOKUP(C4,Headcount!C:C,Headcount!C:C)),"Invalid FK","Valid") -> Valid
A5: TRX100003 | B5: 45102 | C5: 212157.95 | D5: Revenue | E5: Service | F5: Enterprise | G5: West | H5: CUST10027 | J5: Develop many it I rich floor decide. | K5: =IF(ISNA(XLOOKUP(A5,Customers!A:A,Customers!A:A)),"Invalid FK","Valid") -> Valid | L5: =IF(ISNA(XLOOKUP(B5,Vendors!A:A,Vendors!A:A)),"Invalid FK","Valid") -> Valid | M5: =IF(ISNA(XLOOKUP(C5,Headcount!C:C,Headcount!C:C)),"Invalid FK","Valid") -> Valid
A6: TRX100004 | B6: 45245 | C6: -35944.73 | D6: Expense | E6: Rent | F6: Enterprise | G6: North | I6: VEND1046 | J6: Choose thought teach never. | K6: =IF(ISNA(XLOOKUP(A6,Customers!A:A,Customers!A:A)),"Invalid FK","Valid") -> Valid | L6: =IF(ISNA(XLOOKUP(B6,Vendors!A:A,Vendors!A:A)),"Invalid FK","Valid") -> Valid | M6: =IF(ISNA(XLOOKUP(C6,Headcount!C:C,Headcount!C:C)),"Invalid FK","Valid") -> Valid
A7: TRX100005 | B7: 44989 | C7: 90953.83 | D7: Revenue | E7: Service | F7: Retail | G7: South | H7: CUST10332 | J7: Dinner present unit lay course. | K7: =IF(ISNA(XLOOKUP(A7,Customers!A:A,Customers!A:A)),"Invalid FK","Valid") -> Valid | L7: =IF(ISNA(XLOOKUP(B7,Vendors!A:A,Vendors!A:A)),"Invalid FK","Valid") -> Valid | M7: =IF(ISNA(XLOOKUP(C7,Headcount!C:C,Headcount!C:C)),"Invalid FK","Valid") -> Valid
A8: TRX100006 | B8: 45115 | C8: 73251.21 | D8: Revenue | E8: Service | F8: Online | G8: West | H8: CUST10270 | J8: Data ago arm care hundred represent wonder. | K8: =IF(ISNA(XLOOKUP(A8,Customers!A:A,Customers!A:A)),"Invalid FK","Valid") -> Valid | L8: =IF(ISNA(XLOOKUP(B8,Vendors!A:A,Vendors!A:A)),"Invalid FK","Valid") -> Valid | M8: =IF(ISNA(XLOOKUP(C8,Headcount!C:C,Headcount!C:C)),"Invalid FK","Valid") -> Valid
A9: TRX100007 | B9: 44644 | C9: -21064.02 | D9: Expense | E9: Marketing | F9: Online | G9: East | I9: VEND1115 | J9: Sign such remember range ability. | K9: =IF(ISNA(XLOOKUP(A9,Customers!A:A,Customers!A:A)),"Invalid FK","Valid") -> Valid | L9: =IF(ISNA(XLOOKUP(B9,Vendors!A:A,Vendors!A:A)),"Invalid FK","Valid") -> Valid | M9: =IF(ISNA(XLOOKUP(C9,Headcount!C:C,Headcount!C:C)),"Invalid FK","Valid") -> Valid
A10: TRX100008 | B10: 44775 | C10: 136347.73 | D10: Revenue | E10: Product | F10: Retail | G10: West | H10: CUST10168 | J10: Poor similar feeling close require probably rather thought. | K10: =IF(ISNA(XLOOKUP(A10,Customers!A:A,Customers!A:A)),"Invalid FK","Valid") -> Valid | L10: =IF(ISNA(XLOOKUP(B10,Vendors!A:A,Vendors!A:A)),"Invalid FK","Valid") -> Valid | M10: =IF(ISNA(XLOOKUP(C10,Headcount!C:C,Headcount!C:C)),"Invalid FK","Valid") -> Valid
A11: TRX100009 | B11: 45094 | C11: 159482 | D11: Revenue | E11: Product | F11: Retail | G11: West | H11: CUST10151 | J11: Cause worker statement office able foot. | K11: =IF(ISNA(XLOOKUP(A11,Customers!A:A,Customers!A:A)),"Invalid FK","Valid") -> Valid | L11: =IF(ISNA(XLOOKUP(B11,Vendors!A:A,Vendors!A:A)),"Invalid FK","Valid") -> Valid | M11: =IF(ISNA(XLOOKUP(C11,Headcount!C:C,Headcount!C:C)),"Invalid FK","Valid") -> Valid
A12: TRX100010 | B12: 44749 | C12: 15882.36 | D12: Equity | E12: Equity | F12: Retail | G12: South | J12: Ready enter quite attack resource list commercial. | K12: =IF(ISNA(XLOOKUP(A12,Customers!A:A,Customers!A:A)),"Invalid FK","Valid") -> Valid | L12: =IF(ISNA(XLOOKUP(B12,Vendors!A:A,Vendors!A:A)),"Invalid FK","Valid") -> Valid | M12: =IF(ISNA(XLOOKUP(C12,Headcount!C:C,Headcount!C:C)),"Invalid FK","Valid") -> Valid
A13: TRX100011 | B13: 44781 | C13: 217487.82 | D13: Revenue | E13: Product | F13: Online | G13: North | H13: CUST10353 | J13: Before green media feeling Mr half trouble. | K13: =IF(ISNA(XLOOKUP(A13,Customers!A:A,Customers!A:A)),"Invalid FK","Valid") -> Valid | L13: =IF(ISNA(XLOOKUP(B13,Vendors!A:A,Vendors!A:A)),"Invalid FK","Valid") -> Valid | M13: =IF(ISNA(XLOOKUP(C13,Headcount!C:C,Headcount!C:C)),"Invalid FK","Valid") -> Valid
A14: TRX100012 | B14: 45001 | C14: -8913.27 | D14: Expense | E14: Other | F14: Enterprise | G14: East | I14: VEND1067 | J14: Rise discover visit security end buy medical think. | K14: =IF(ISNA(XLOOKUP(A14,Customers!A:A,Customers!A:A)),"Invalid FK","Valid") -> Valid | L14: =IF(ISNA(XLOOKUP(B14,Vendors!A:A,Vendors!A:A)),"Invalid FK","Valid") -> Valid | M14: =IF(ISNA(XLOOKUP(C14,Headcount!C:C,Headcount!C:C)),"Invalid FK","Valid") -> Valid
A15: TRX100013 | B15: 45270 | C15: 139523.96 | D15: Revenue | E15: Service | F15: Retail | G15: North | H15: CUST10243 | J15: Military line exist little education family world. | K15: =IF(ISNA(XLOOKUP(A15,Customers!A:A,Customers!A:A)),"Invalid FK","Valid") -> Valid | L15: =IF(ISNA(XLOOKUP(B15,Vendors!A:A,Vendors!A:A)),"Invalid FK","Valid") -> Valid | M15: =IF(ISNA(XLOOKUP(C15,Headcount!C:C,Headcount!C:C)),"Invalid FK","Valid") -> Valid
A16: TRX100014 | B16: 45125 | C16: 165589.04 | D16: Revenue | E16: Service | F16: Online | G16: East | H16: CUST10357 | J16: Artist place loss morning. | K16: =IF(ISNA(XLOOKUP(A16,Customers!A:A,Customers!A:A)),"Invalid FK","Valid") -> Valid | L16: =IF(ISNA(XLOOKUP(B16,Vendors!A:A,Vendors!A:A)),"Invalid FK","Valid") -> Valid | M16: =IF(ISNA(XLOOKUP(C16,Headcount!C:C,Headcount!C:C)),"Invalid FK","Valid") -> Valid
A17: TRX100015 | B17: 44952 | C17: 262541.15 | D17: Revenue | E17: Service | F17: Retail | G17: West | H17: CUST10045 | J17: Game evidence support skill pretty. | K17: =IF(ISNA(XLOOKUP(A17,Customers!A:A,Customers!A:A)),"Invalid FK","Valid") -> Valid | L17: =IF(ISNA(XLOOKUP(B17,Vendors!A:A,Vendors!A:A)),"Invalid FK","Valid") -> Valid | M17: =IF(ISNA(XLOOKUP(C17,Headcount!C:C,Headcount!C:C)),"Invalid FK","Valid") -> Valid
A18: TRX100016 | B18: 45087 | C18: 152113.39 | D18: Revenue | E18: Service | F18: Online | G18: South | H18: CUST10120 | J18: Bad author generation decade increase. | K18: =IF(ISNA(XLOOKUP(A18,Customers!A:A,Customers!A:A)),"Invalid FK","Valid") -> Valid | L18: =IF(ISNA(XLOOKUP(B18,Vendors!A:A,Vendors!A:A)),"Invalid FK","Valid") -> Valid | M18: =IF(ISNA(XLOOKUP(C18,Headcount!C:C,Headcount!C:C)),"Invalid FK","Valid") -> Valid
A19: TRX100017 | B19: 44726 | C19: 107495.7 | D19: Revenue | E19: Service | F19: Online | G19: North | H19: CUST10228 | J19: Left own eat wife tell with. | K19: =IF(ISNA(XLOOKUP(A19,Customers!A:A,Customers!A:A)),"Invalid FK","Valid") -> Valid | L19: =IF(ISNA(XLOOKUP(B19,Vendors!A:A,Vendors!A:A)),"Invalid FK","Valid") -> Valid | M19: =IF(ISNA(XLOOKUP(C19,Headcount!C:C,Headcount!C:C)),"Invalid FK","Valid") -> Valid
A20: TRX100018 | B20: 45190 | C20: 83127.62 | D20: Revenue | E20: Subscription | F20: Online | G20: West | H20: CUST10333 | J20: Individual first region. | K20: =IF(ISNA(XLOOKUP(A20,Customers!A:A,Customers!A:A)),"Invalid FK","Valid") -> Valid | L20: =IF(ISNA(XLOOKUP(B20,Vendors!A:A,Vendors!A:A)),"Invalid FK","Valid") -> Valid | M20: =IF(ISNA(XLOOKUP(C20,Headcount!C:C,Headcount!C:C)),"Invalid FK","Valid") -> Valid
A21: TRX100019 | B21: 44793 | C21: 145634.47 | D21: Revenue | E21: Service | F21: Enterprise | G21: West | H21: CUST10302 | J21: Rise war shake doctor. | K21: =IF(ISNA(XLOOKUP(A21,Customers!A:A,Customers!A:A)),"Invalid FK","Valid") -> Valid | L21: =IF(ISNA(XLOOKUP(B21,Vendors!A:A,Vendors!A:A)),"Invalid FK","Valid") -> Valid | M21: =IF(ISNA(XLOOKUP(C21,Headcount!C:C,Headcount!C:C)),"Invalid FK","Valid") -> Valid
A22: TRX100020 | B22: 45062 | C22: 167566.97 | D22: Revenue | E22: Service | F22: Retail | G22: North | H22: CUST10042 | J22: Before expect allow job one set. | K22: =IF(ISNA(XLOOKUP(A22,Customers!A:A,Customers!A:A)),"Invalid FK","Valid") -> Valid | L22: =IF(ISNA(XLOOKUP(B22,Vendors!A:A,Vendors!A:A)),"Invalid FK","Valid") -> Valid | M22: =IF(ISNA(XLOOKUP(C22,Headcount!C:C,Headcount!C:C)),"Invalid FK","Valid") -> Valid
A23: TRX100021 | B23: 44726 | C23: -2000 | D23: Expense | E23: Rent | F23: Online | G23: West | I23: VEND1022 | J23: Side official leave seem financial. | K23: =IF(ISNA(XLOOKUP(A23,Customers!A:A,Customers!A:A)),"Invalid FK","Valid") -> Valid | L23: =IF(ISNA(XLOOKUP(B23,Vendors!A:A,Vendors!A:A)),"Invalid FK","Valid") -> Valid | M23: =IF(ISNA(XLOOKUP(C23,Headcount!C:C,Headcount!C:C)),"Invalid FK","Valid") -> Valid
A24: TRX100022 | B24: 44998 | C24: 203374.65 | D24: Revenue | E24: Service | F24: Online | G24: South | H24: CUST10021 | J24: Must require bit relate Congress local improve organization. | K24: =IF(ISNA(XLOOKUP(A24,Customers!A:A,Customers!A:A)),"Invalid FK","Valid") -> Valid | L24: =IF(ISNA(XLOOKUP(B24,Vendors!A:A,Vendors!A:A)),"Invalid FK","Valid") -> Valid | M24: =IF(ISNA(XLOOKUP(C24,Headcount!C:C,Headcount!C:C)),"Invalid FK","Valid") -> Valid
A25: TRX100023 | B25: 45189 | C25: 171433.19 | D25: Revenue | E25: Product | F25: Enterprise | G25: West | H25: CUST10218 | J25: Identify loss across fact government sea upon. | K25: =IF(ISNA(XLOOKUP(A25,Customers!A:A,Customers!A:A)),"Invalid FK","Valid") -> Valid | L25: =IF(ISNA(XLOOKUP(B25,Vendors!A:A,Vendors!A:A)),"Invalid FK","Valid") -> Valid | M25: =IF(ISNA(XLOOKUP(C25,Headcount!C:C,Headcount!C:C)),"Invalid FK","Valid") -> Valid
A26: TRX100024 | B26: 44850 | C26: -60198.87 | D26: Expense | E26: Payroll | F26: Enterprise | G26: North | I26: VEND1058 | J26: Big fine cause full reality heart condition another. | K26: =IF(ISNA(XLOOKUP(A26,Customers!A:A,Customers!A:A)),"Invalid FK","Valid") -> Valid | L26: =IF(ISNA(XLOOKUP(B26,Vendors!A:A,Vendors!A:A)),"Invalid FK","Valid") -> Valid | M26: =IF(ISNA(XLOOKUP(C26,Headcount!C:C,Headcount!C:C)),"Invalid FK","Valid") -> Valid
A27: TRX100025 | B27: 45097 | C27: -40143.88 | D27: Expense | E27: Rent | F27: Retail | G27: West | I27: VEND1037 | J27: Good owner financial any result summer physical. | K27: =IF(ISNA(XLOOKUP(A27,Customers!A:A,Customers!A:A)),"Invalid FK","Valid") -> Valid | L27: =IF(ISNA(XLOOKUP(B27,Vendors!A:A,Vendors!A:A)),"Invalid FK","Valid") -> Valid | M27: =IF(ISNA(XLOOKUP(C27,Headcount!C:C,Headcount!C:C)),"Invalid FK","Valid") -> Valid
A28: TRX100026 | B28: 45208 | C28: -38329 | D28: Expense | E28: Marketing | F28: Enterprise | G28: West | I28: VEND1049 | J28: Sport note decide who modern car knowledge. | K28: =IF(ISNA(XLOOKUP(A28,Customers!A:A,Customers!A:A)),"Invalid FK","Valid") -> Valid | L28: =IF(ISNA(XLOOKUP(B28,Vendors!A:A,Vendors!A:A)),"Invalid FK","Valid") -> Valid | M28: =IF(ISNA(XLOOKUP(C28,Headcount!C:C,Headcount!C:C)),"Invalid FK","Valid") -> Valid
A29: TRX100027 | B29: 44901 | C29: 193475.45 | D29: Revenue | E29: Service | F29: Retail | G29: South | H29: CUST10146 | J29: Game step assume late home order morning to. | K29: =IF(ISNA(XLOOKUP(A29,Customers!A:A,Customers!A:A)),"Invalid FK","Valid") -> Valid | L29: =IF(ISNA(XLOOKUP(B29,Vendors!A:A,Vendors!A:A)),"Invalid FK","Valid") -> Valid | M29: =IF(ISNA(XLOOKUP(C29,Headcount!C:C,Headcount!C:C)),"Invalid FK","Valid") -> Valid
A30: TRX100028 | B30: 45002 | C30: 139672.98 | D30: Revenue | E30: Subscription | F30: Enterprise | G30: South | H30: CUST10074 | J30: Nature need environment operation country easy across choice. | K30: =IF(ISNA(XLOOKUP(A30,Customers!A:A,Customers!A:A)),"Invalid FK","Valid") -> Valid | L30: =IF(ISNA(XLOOKUP(B30,Vendors!A:A,Vendors!A:A)),"Invalid FK","Valid") -> Valid | M30: =IF(ISNA(XLOOKUP(C30,Headcount!C:C,Headcount!C:C)),"Invalid FK","Valid") -> Valid
A31: TRX100029 | B31: 45188 | C31: 198385.78 | D31: Revenue | E31: Subscription | F31: Enterprise | G31: North | H31: CUST10011 | J31: Scientist particularly include true listen happy. | K31: =IF(ISNA(XLOOKUP(A31,Customers!A:A,Customers!A:A)),"Invalid FK","Valid") -> Valid | L31: =IF(ISNA(XLOOKUP(B31,Vendors!A:A,Vendors!A:A)),"Invalid FK","Valid") -> Valid | M31: =IF(ISNA(XLOOKUP(C31,Headcount!C:C,Headcount!C:C)),"Invalid FK","Valid") -> Valid
A32: TRX100030 | B32: 44814 | C32: 137108.16 | D32: Revenue | E32: Service | F32: Enterprise | G32: East | H32: CUST10325 | J32: Citizen help never simple course. | K32: =IF(ISNA(XLOOKUP(A32,Customers!A:A,Customers!A:A)),"Invalid FK","Valid") -> Valid | L32: =IF(ISNA(XLOOKUP(B32,Vendors!A:A,Vendors!A:A)),"Invalid FK","Valid") -> Valid | M32: =IF(ISNA(XLOOKUP(C32,Headcount!C:C,Headcount!C:C)),"Invalid FK","Valid") -> Valid
A33: TRX100031 | B33: 44624 | C33: -44326.21 | D33: Expense | E33: Other | F33: Retail | G33: East | I33: VEND1053 | J33: Billion newspaper modern fine career somebody. | K33: =IF(ISNA(XLOOKUP(A33,Customers!A:A,Customers!A:A)),"Invalid FK","Valid") -> Valid | L33: =IF(ISNA(XLOOKUP(B33,Vendors!A:A,Vendors!A:A)),"Invalid FK","Valid") -> Valid | M33: =IF(ISNA(XLOOKUP(C33,Headcount!C:C,Headcount!C:C)),"Invalid FK","Valid") -> Valid
A34: TRX100032 | B34: 44970 | C34: 162088.99 | D34: Revenue | E34: Service | F34: Enterprise | G34: North | H34: CUST10203 | J34: Wall campaign might anyone. | K34: =IF(ISNA(XLOOKUP(A34,Customers!A:A,Customers!A:A)),"Invalid FK","Valid") -> Valid | L34: =IF(ISNA(XLOOKUP(B34,Vendors!A:A,Vendors!A:A)),"Invalid FK","Valid") -> Valid | M34: =IF(ISNA(XLOOKUP(C34,Headcount!C:C,Headcount!C:C)),"Invalid FK","Valid") -> Valid
A35: TRX100033 | B35: 44847 | C35: 138103.68 | D35: Revenue | E35: Subscription | F35: Online | G35: North | H35: CUST10151 | J35: Could impact decide key. | K35: =IF(ISNA(XLOOKUP(A35,Customers!A:A,Customers!A:A)),"Invalid FK","Valid") -> Valid | L35: =IF(ISNA(XLOOKUP(B35,Vendors!A:A,Vendors!A:A)),"Invalid FK","Valid") -> Valid | M35: =IF(ISNA(XLOOKUP(C35,Headcount!C:C,Headcount!C:C)),"Invalid FK","Valid") -> Valid
A36: TRX100034 | B36: 44695 | C36: -10197.61 | D36: Expense | E36: Utilities | F36: Retail | G36: East | I36: VEND1014 | J36: Imagine must who discover since painting. | K36: =IF(ISNA(XLOOKUP(A36,Customers!A:A,Customers!A:A)),"Invalid FK","Valid") -> Valid | L36: =IF(ISNA(XLOOKUP(B36,Vendors!A:A,Vendors!A:A)),"Invalid FK","Valid") -> Valid | M36: =IF(ISNA(XLOOKUP(C36,Headcount!C:C,Headcount!C:C)),"Invalid FK","Valid") -> Valid
A37: TRX100035 | B37: 45145 | C37: -62926.94 | D37: Expense | E37: Marketing | F37: Retail | G37: West | I37: VEND1093 | J37: Training nor arrive. | K37: =IF(ISNA(XLOOKUP(A37,Customers!A:A,Customers!A:A)),"Invalid FK","Valid") -> Valid | L37: =IF(ISNA(XLOOKUP(B37,Vendors!A:A,Vendors!A:A)),"Invalid FK","Valid") -> Valid | M37: =IF(ISNA(XLOOKUP(C37,Headcount!C:C,Headcount!C:C)),"Invalid FK","Valid") -> Valid
A38: TRX100036 | B38: 45195 | C38: 144593.87 | D38: Revenue | E38: Service | F38: Enterprise | G38: East | H38: CUST10086 | J38: Field some arrive society everybody guy public. | K38: =IF(ISNA(XLOOKUP(A38,Customers!A:A,Customers!A:A)),"Invalid FK","Valid") -> Valid | L38: =IF(ISNA(XLOOKUP(B38,Vendors!A:A,Vendors!A:A)),"Invalid FK","Valid") -> Valid | M38: =IF(ISNA(XLOOKUP(C38,Headcount!C:C,Headcount!C:C)),"Invalid FK","Valid") -> Valid
A39: TRX100037 | B39: 44595 | C39: 38814.58 | D39: Revenue | E39: Product | F39: Retail | G39: North | H39: CUST10013 | J39: Order agreement mind everything. | K39: =IF(ISNA(XLOOKUP(A39,Customers!A:A,Customers!A:A)),"Invalid FK","Valid") -> Valid | L39: =IF(ISNA(XLOOKUP(B39,Vendors!A:A,Vendors!A:A)),"Invalid FK","Valid") -> Valid | M39: =IF(ISNA(XLOOKUP(C39,Headcount!C:C,Headcount!C:C)),"Invalid FK","Valid") -> Valid
A40: TRX100038 | B40: 44983 | C40: -36977.97 | D40: Expense | E40: Rent | F40: Online | G40: East | I40: VEND1082 | J40: Watch would miss interview water trouble. | K40: =IF(ISNA(XLOOKUP(A40,Customers!A:A,Customers!A:A)),"Invalid FK","Valid") -> Valid | L40: =IF(ISNA(XLOOKUP(B40,Vendors!A:A,Vendors!A:A)),"Invalid FK","Valid") -> Valid | M40: =IF(ISNA(XLOOKUP(C40,Headcount!C:C,Headcount!C:C)),"Invalid FK","Valid") -> Valid
...

Sheet Financial_Transactions_Clean
A1: transaction_id | B1: transaction_date | C1: amount | D1: account_type | E1: category | F1: business_unit | G1: region | H1: customer_id | I1: vendor_id | J1: description | K1: customer_fk_check | L1: vendor_fk_check | M1: headcount_fk_check | N1: missing_flag | O1: outlier_flag | P1: validation_status
A2: TRX100000 | B2: 45172 | C2: -66631.73 | D2: Expense | E2: Supplies | F2: Online | G2: West | I2: VEND1053 | J2: Begin Catch Control Dark Practice. | K2: Valid | L2: Valid | M2: Valid | N2: =IF(OR(B2="",C2="",D2="",F2=""),"Missing","OK") -> OK | O2: =IF(OR(Table1_17[[#This Row],[amount]]<$Y$8,Table1_17[[#This Row],[amount]]>$Y$7),"Outlier","Normal") -> Normal | P2: =IF(OR(Table1_17[[#This Row],[missing_flag]]="Missing",Table1_17[[#This Row],[outlier_flag]]="Outliers"),"Review","Valid") -> Valid | X2: Q1 = | Y2: =_xlfn.QUARTILE.EXC(C:C,1) -> -33703.118
A3: TRX100001 | B3: 45182 | C3: -54305.58 | D3: Expense | E3: Utilities | F3: Enterprise | G3: East | I3: VEND1059 | J3: Style Guy Soldier Boy Energy Above. | K3: Valid | L3: Valid | M3: Valid | N3: =IF(OR(B3="",C3="",D3="",F3=""),"Missing","OK") -> OK | O3: =IF(OR(Table1_17[[#This Row],[amount]]<$Y$8,Table1_17[[#This Row],[amount]]>$Y$7),"Outlier","Normal") -> Normal | P3: =IF(OR(Table1_17[[#This Row],[missing_flag]]="Missing",Table1_17[[#This Row],[outlier_flag]]="Outliers"),"Review","Valid") -> Valid | X3: Q3 = | Y3: =_xlfn.QUARTILE.EXC(C:C,3) -> 157304.32
A4: TRX100002 | B4: 45104 | C4: 146074.92 | D4: Revenue | E4: Subscription | F4: Online | G4: East | H4: CUST10122 | J4: Skill Surface Drug Personal Western. | K4: Valid | L4: Valid | M4: Valid | N4: =IF(OR(B4="",C4="",D4="",F4=""),"Missing","OK") -> OK | O4: =IF(OR(Table1_17[[#This Row],[amount]]<$Y$8,Table1_17[[#This Row],[amount]]>$Y$7),"Outlier","Normal") -> Normal | P4: =IF(OR(Table1_17[[#This Row],[missing_flag]]="Missing",Table1_17[[#This Row],[outlier_flag]]="Outliers"),"Review","Valid") -> Valid
A5: TRX100003 | B5: 45102 | C5: 212157.95 | D5: Revenue | E5: Service | F5: Enterprise | G5: West | H5: CUST10027 | J5: Develop Many It I Rich Floor Decide. | K5: Valid | L5: Valid | M5: Valid | N5: =IF(OR(B5="",C5="",D5="",F5=""),"Missing","OK") -> OK | O5: =IF(OR(Table1_17[[#This Row],[amount]]<$Y$8,Table1_17[[#This Row],[amount]]>$Y$7),"Outlier","Normal") -> Normal | P5: =IF(OR(Table1_17[[#This Row],[missing_flag]]="Missing",Table1_17[[#This Row],[outlier_flag]]="Outliers"),"Review","Valid") -> Valid | X5: IQR = | Y5: =Y3-Y2 -> 191007.43
A6: TRX100004 | B6: 45245 | C6: -35944.73 | D6: Expense | E6: Rent | F6: Enterprise | G6: North | I6: VEND1046 | J6: Choose Thought Teach Never. | K6: Valid | L6: Valid | M6: Valid | N6: =IF(OR(B6="",C6="",D6="",F6=""),"Missing","OK") -> OK | O6: =IF(OR(Table1_17[[#This Row],[amount]]<$Y$8,Table1_17[[#This Row],[amount]]>$Y$7),"Outlier","Normal") -> Normal | P6: =IF(OR(Table1_17[[#This Row],[missing_flag]]="Missing",Table1_17[[#This Row],[outlier_flag]]="Outliers"),"Review","Valid") -> Valid
A7: TRX100005 | B7: 44989 | C7: 90953.83 | D7: Revenue | E7: Service | F7: Retail | G7: South | H7: CUST10332 | J7: Dinner Present Unit Lay Course. | K7: Valid | L7: Valid | M7: Valid | N7: =IF(OR(B7="",C7="",D7="",F7=""),"Missing","OK") -> OK | O7: =IF(OR(Table1_17[[#This Row],[amount]]<$Y$8,Table1_17[[#This Row],[amount]]>$Y$7),"Outlier","Normal") -> Normal | P7: =IF(OR(Table1_17[[#This Row],[missing_flag]]="Missing",Table1_17[[#This Row],[outlier_flag]]="Outliers"),"Review","Valid") -> Valid | X7: Upper Limit = | Y7: =Y3+1.5*Y5 -> 443815.47
A8: TRX100006 | B8: 45115 | C8: 73251.21 | D8: Revenue | E8: Service | F8: Online | G8: West | H8: CUST10270 | J8: Data Ago Arm Care Hundred Represent Wonder. | K8: Valid | L8: Valid | M8: Valid | N8: =IF(OR(B8="",C8="",D8="",F8=""),"Missing","OK") -> OK | O8: =IF(OR(Table1_17[[#This Row],[amount]]<$Y$8,Table1_17[[#This Row],[amount]]>$Y$7),"Outlier","Normal") -> Normal | P8: =IF(OR(Table1_17[[#This Row],[missing_flag]]="Missing",Table1_17[[#This Row],[outlier_flag]]="Outliers"),"Review","Valid") -> Valid | X8: Lower Limit = | Y8: =Y2-1.5*Y5 -> -320214.27
A9: TRX100007 | B9: 44644 | C9: -21064.02 | D9: Expense | E9: Marketing | F9: Online | G9: East | I9: VEND1115 | J9: Sign Such Remember Range Ability. | K9: Valid | L9: Valid | M9: Valid | N9: =IF(OR(B9="",C9="",D9="",F9=""),"Missing","OK") -> OK | O9: =IF(OR(Table1_17[[#This Row],[amount]]<$Y$8,Table1_17[[#This Row],[amount]]>$Y$7),"Outlier","Normal") -> Normal | P9: =IF(OR(Table1_17[[#This Row],[missing_flag]]="Missing",Table1_17[[#This Row],[outlier_flag]]="Outliers"),"Review","Valid") -> Valid
A10: TRX100008 | B10: 44775 | C10: 136347.73 | D10: Revenue | E10: Product | F10: Retail | G10: West | H10: CUST10168 | J10: Poor Similar Feeling Close Require Probably Rather Thought. | K10: Valid | L10: Valid | M10: Valid | N10: =IF(OR(B10="",C10="",D10="",F10=""),"Missing","OK") -> OK | O10: =IF(OR(Table1_17[[#This Row],[amount]]<$Y$8,Table1_17[[#This Row],[amount]]>$Y$7),"Outlier","Normal") -> Normal | P10: =IF(OR(Table1_17[[#This Row],[missing_flag]]="Missing",Table1_17[[#This Row],[outlier_flag]]="Outliers"),"Review","Valid") -> Valid
A11: TRX100009 | B11: 45094 | C11: 159482 | D11: Revenue | E11: Product | F11: Retail | G11: West | H11: CUST10151 | J11: Cause Worker Statement Office Able Foot. | K11: Valid | L11: Valid | M11: Valid | N11: =IF(OR(B11="",C11="",D11="",F11=""),"Missing","OK") -> OK | O11: =IF(OR(Table1_17[[#This Row],[amount]]<$Y$8,Table1_17[[#This Row],[amount]]>$Y$7),"Outlier","Normal") -> Normal | P11: =IF(OR(Table1_17[[#This Row],[missing_flag]]="Missing",Table1_17[[#This Row],[outlier_flag]]="Outliers"),"Review","Valid") -> Valid
A12: TRX100010 | B12: 44749 | C12: 15882.36 | D12: Equity | E12: Equity | F12: Retail | G12: South | J12: Ready Enter Quite Attack Resource List Commercial. | K12: Valid | L12: Valid | M12: Valid | N12: =IF(OR(B12="",C12="",D12="",F12=""),"Missing","OK") -> OK | O12: =IF(OR(Table1_17[[#This Row],[amount]]<$Y$8,Table1_17[[#This Row],[amount]]>$Y$7),"Outlier","Normal") -> Normal | P12: =IF(OR(Table1_17[[#This Row],[missing_flag]]="Missing",Table1_17[[#This Row],[outlier_flag]]="Outliers"),"Review","Valid") -> Valid
A13: TRX100011 | B13: 44781 | C13: 217487.82 | D13: Revenue | E13: Product | F13: Online | G13: North | H13: CUST10353 | J13: Before Green Media Feeling Mr Half Trouble. | K13: Valid | L13: Valid | M13: Valid | N13: =IF(OR(B13="",C13="",D13="",F13=""),"Missing","OK") -> OK | O13: =IF(OR(Table1_17[[#This Row],[amount]]<$Y$8,Table1_17[[#This Row],[amount]]>$Y$7),"Outlier","Normal") -> Normal | P13: =IF(OR(Table1_17[[#This Row],[missing_flag]]="Missing",Table1_17[[#This Row],[outlier_flag]]="Outliers"),"Review","Valid") -> Valid
A14: TRX100012 | B14: 45001 | C14: -8913.27 | D14: Expense | E14: Other | F14: Enterprise | G14: East | I14: VEND1067 | J14: Rise Discover Visit Security End Buy Medical Think. | K14: Valid | L14: Valid | M14: Valid | N14: =IF(OR(B14="",C14="",D14="",F14=""),"Missing","OK") -> OK | O14: =IF(OR(Table1_17[[#This Row],[amount]]<$Y$8,Table1_17[[#This Row],[amount]]>$Y$7),"Outlier","Normal") -> Normal | P14: =IF(OR(Table1_17[[#This Row],[missing_flag]]="Missing",Table1_17[[#This Row],[outlier_flag]]="Outliers"),"Review","Valid") -> Valid
A15: TRX100013 | B15: 45270 | C15: 139523.96 | D15: Revenue | E15: Service | F15: Retail | G15: North | H15: CUST10243 | J15: Military Line Exist Little Education Family World. | K15: Valid | L15: Valid | M15: Valid | N15: =IF(OR(B15="",C15="",D15="",F15=""),"Missing","OK") -> OK | O15: =IF(OR(Table1_17[[#This Row],[amount]]<$Y$8,Table1_17[[#This Row],[amount]]>$Y$7),"Outlier","Normal") -> Normal | P15: =IF(OR(Table1_17[[#This Row],[missing_flag]]="Missing",Table1_17[[#This Row],[outlier_flag]]="Outliers"),"Review","Valid") -> Valid
A16: TRX100014 | B16: 45125 | C16: 165589.04 | D16: Revenue | E16: Service | F16: Online | G16: East | H16: CUST10357 | J16: Artist Place Loss Morning. | K16: Valid | L16: Valid | M16: Valid | N16: =IF(OR(B16="",C16="",D16="",F16=""),"Missing","OK") -> OK | O16: =IF(OR(Table1_17[[#This Row],[amount]]<$Y$8,Table1_17[[#This Row],[amount]]>$Y$7),"Outlier","Normal") -> Normal | P16: =IF(OR(Table1_17[[#This Row],[missing_flag]]="Missing",Table1_17[[#This Row],[outlier_flag]]="Outliers"),"Review","Valid") -> Valid
A17: TRX100015 | B17: 44952 | C17: 262541.15 | D17: Revenue | E17: Service | F17: Retail | G17: West | H17: CUST10045 | J17: Game Evidence Support Skill Pretty. | K17: Valid | L17: Valid | M17: Valid | N17: =IF(OR(B17="",C17="",D17="",F17=""),"Missing","OK") -> OK | O17: =IF(OR(Table1_17[[#This Row],[amount]]<$Y$8,Table1_17[[#This Row],[amount]]>$Y$7),"Outlier","Normal") -> Normal | P17: =IF(OR(Table1_17[[#This Row],[missing_flag]]="Missing",Table1_17[[#This Row],[outlier_flag]]="Outliers"),"Review","Valid") -> Valid
A18: TRX100016 | B18: 45087 | C18: 152113.39 | D18: Revenue | E18: Service | F18: Online | G18: South | H18: CUST10120 | J18: Bad Author Generation Decade Increase. | K18: Valid | L18: Valid | M18: Valid | N18: =IF(OR(B18="",C18="",D18="",F18=""),"Missing","OK") -> OK | O18: =IF(OR(Table1_17[[#This Row],[amount]]<$Y$8,Table1_17[[#This Row],[amount]]>$Y$7),"Outlier","Normal") -> Normal | P18: =IF(OR(Table1_17[[#This Row],[missing_flag]]="Missing",Table1_17[[#This Row],[outlier_flag]]="Outliers"),"Review","Valid") -> Valid
A19: TRX100017 | B19: 44726 | C19: 107495.7 | D19: Revenue | E19: Service | F19: Online | G19: North | H19: CUST10228 | J19: Left Own Eat Wife Tell With. | K19: Valid | L19: Valid | M19: Valid | N19: =IF(OR(B19="",C19="",D19="",F19=""),"Missing","OK") -> OK | O19: =IF(OR(Table1_17[[#This Row],[amount]]<$Y$8,Table1_17[[#This Row],[amount]]>$Y$7),"Outlier","Normal") -> Normal | P19: =IF(OR(Table1_17[[#This Row],[missing_flag]]="Missing",Table1_17[[#This Row],[outlier_flag]]="Outliers"),"Review","Valid") -> Valid
A20: TRX100018 | B20: 45190 | C20: 83127.62 | D20: Revenue | E20: Subscription | F20: Online | G20: West | H20: CUST10333 | J20: Individual First Region. | K20: Valid | L20: Valid | M20: Valid | N20: =IF(OR(B20="",C20="",D20="",F20=""),"Missing","OK") -> OK | O20: =IF(OR(Table1_17[[#This Row],[amount]]<$Y$8,Table1_17[[#This Row],[amount]]>$Y$7),"Outlier","Normal") -> Normal | P20: =IF(OR(Table1_17[[#This Row],[missing_flag]]="Missing",Table1_17[[#This Row],[outlier_flag]]="Outliers"),"Review","Valid") -> Valid
A21: TRX100019 | B21: 44793 | C21: 145634.47 | D21: Revenue | E21: Service | F21: Enterprise | G21: West | H21: CUST10302 | J21: Rise War Shake Doctor. | K21: Valid | L21: Valid | M21: Valid | N21: =IF(OR(B21="",C21="",D21="",F21=""),"Missing","OK") -> OK | O21: =IF(OR(Table1_17[[#This Row],[amount]]<$Y$8,Table1_17[[#This Row],[amount]]>$Y$7),"Outlier","Normal") -> Normal | P21: =IF(OR(Table1_17[[#This Row],[missing_flag]]="Missing",Table1_17[[#This Row],[outlier_flag]]="Outliers"),"Review","Valid") -> Valid
A22: TRX100020 | B22: 45062 | C22: 167566.97 | D22: Revenue | E22: Service | F22: Retail | G22: North | H22: CUST10042 | J22: Before Expect Allow Job One Set. | K22: Valid | L22: Valid | M22: Valid | N22: =IF(OR(B22="",C22="",D22="",F22=""),"Missing","OK") -> OK | O22: =IF(OR(Table1_17[[#This Row],[amount]]<$Y$8,Table1_17[[#This Row],[amount]]>$Y$7),"Outlier","Normal") -> Normal | P22: =IF(OR(Table1_17[[#This Row],[missing_flag]]="Missing",Table1_17[[#This Row],[outlier_flag]]="Outliers"),"Review","Valid") -> Valid
A23: TRX100021 | B23: 44726 | C23: -2000 | D23: Expense | E23: Rent | F23: Online | G23: West | I23: VEND1022 | J23: Side Official Leave Seem Financial. | K23: Valid | L23: Valid | M23: Valid | N23: =IF(OR(B23="",C23="",D23="",F23=""),"Missing","OK") -> OK | O23: =IF(OR(Table1_17[[#This Row],[amount]]<$Y$8,Table1_17[[#This Row],[amount]]>$Y$7),"Outlier","Normal") -> Normal | P23: =IF(OR(Table1_17[[#This Row],[missing_flag]]="Missing",Table1_17[[#This Row],[outlier_flag]]="Outliers"),"Review","Valid") -> Valid
A24: TRX100022 | B24: 44998 | C24: 203374.65 | D24: Revenue | E24: Service | F24: Online | G24: South | H24: CUST10021 | J24: Must Require Bit Relate Congress Local Improve Organization. | K24: Valid | L24: Valid | M24: Valid | N24: =IF(OR(B24="",C24="",D24="",F24=""),"Missing","OK") -> OK | O24: =IF(OR(Table1_17[[#This Row],[amount]]<$Y$8,Table1_17[[#This Row],[amount]]>$Y$7),"Outlier","Normal") -> Normal | P24: =IF(OR(Table1_17[[#This Row],[missing_flag]]="Missing",Table1_17[[#This Row],[outlier_flag]]="Outliers"),"Review","Valid") -> Valid
A25: TRX100023 | B25: 45189 | C25: 171433.19 | D25: Revenue | E25: Product | F25: Enterprise | G25: West | H25: CUST10218 | J25: Identify Loss Across Fact Government Sea Upon. | K25: Valid | L25: Valid | M25: Valid | N25: =IF(OR(B25="",C25="",D25="",F25=""),"Missing","OK") -> OK | O25: =IF(OR(Table1_17[[#This Row],[amount]]<$Y$8,Table1_17[[#This Row],[amount]]>$Y$7),"Outlier","Normal") -> Normal | P25: =IF(OR(Table1_17[[#This Row],[missing_flag]]="Missing",Table1_17[[#This Row],[outlier_flag]]="Outliers"),"Review","Valid") -> Valid
A26: TRX100024 | B26: 44850 | C26: -60198.87 | D26: Expense | E26: Payroll | F26: Enterprise | G26: North | I26: VEND1058 | J26: Big Fine Cause Full Reality Heart Condition Another. | K26: Valid | L26: Valid | M26: Valid | N26: =IF(OR(B26="",C26="",D26="",F26=""),"Missing","OK") -> OK | O26: =IF(OR(Table1_17[[#This Row],[amount]]<$Y$8,Table1_17[[#This Row],[amount]]>$Y$7),"Outlier","Normal") -> Normal | P26: =IF(OR(Table1_17[[#This Row],[missing_flag]]="Missing",Table1_17[[#This Row],[outlier_flag]]="Outliers"),"Review","Valid") -> Valid
A27: TRX100025 | B27: 45097 | C27: -40143.88 | D27: Expense | E27: Rent | F27: Retail | G27: West | I27: VEND1037 | J27: Good Owner Financial Any Result Summer Physical. | K27: Valid | L27: Valid | M27: Valid | N27: =IF(OR(B27="",C27="",D27="",F27=""),"Missing","OK") -> OK | O27: =IF(OR(Table1_17[[#This Row],[amount]]<$Y$8,Table1_17[[#This Row],[amount]]>$Y$7),"Outlier","Normal") -> Normal | P27: =IF(OR(Table1_17[[#This Row],[missing_flag]]="Missing",Table1_17[[#This Row],[outlier_flag]]="Outliers"),"Review","Valid") -> Valid
A28: TRX100026 | B28: 45208 | C28: -38329 | D28: Expense | E28: Marketing | F28: Enterprise | G28: West | I28: VEND1049 | J28: Sport Note Decide Who Modern Car Knowledge. | K28: Valid | L28: Valid | M28: Valid | N28: =IF(OR(B28="",C28="",D28="",F28=""),"Missing","OK") -> OK | O28: =IF(OR(Table1_17[[#This Row],[amount]]<$Y$8,Table1_17[[#This Row],[amount]]>$Y$7),"Outlier","Normal") -> Normal | P28: =IF(OR(Table1_17[[#This Row],[missing_flag]]="Missing",Table1_17[[#This Row],[outlier_flag]]="Outliers"),"Review","Valid") -> Valid
A29: TRX100027 | B29: 44901 | C29: 193475.45 | D29: Revenue | E29: Service | F29: Retail | G29: South | H29: CUST10146 | J29: Game Step Assume Late Home Order Morning To. | K29: Valid | L29: Valid | M29: Valid | N29: =IF(OR(B29="",C29="",D29="",F29=""),"Missing","OK") -> OK | O29: =IF(OR(Table1_17[[#This Row],[amount]]<$Y$8,Table1_17[[#This Row],[amount]]>$Y$7),"Outlier","Normal") -> Normal | P29: =IF(OR(Table1_17[[#This Row],[missing_flag]]="Missing",Table1_17[[#This Row],[outlier_flag]]="Outliers"),"Review","Valid") -> Valid
A30: TRX100028 | B30: 45002 | C30: 139672.98 | D30: Revenue | E30: Subscription | F30: Enterprise | G30: South | H30: CUST10074 | J30: Nature Need Environment Operation Country Easy Across Choice. | K30: Valid | L30: Valid | M30: Valid | N30: =IF(OR(B30="",C30="",D30="",F30=""),"Missing","OK") -> OK | O30: =IF(OR(Table1_17[[#This Row],[amount]]<$Y$8,Table1_17[[#This Row],[amount]]>$Y$7),"Outlier","Normal") -> Normal | P30: =IF(OR(Table1_17[[#This Row],[missing_flag]]="Missing",Table1_17[[#This Row],[outlier_flag]]="Outliers"),"Review","Valid") -> Valid
A31: TRX100029 | B31: 45188 | C31: 198385.78 | D31: Revenue | E31: Subscription | F31: Enterprise | G31: North | H31: CUST10011 | J31: Scientist Particularly Include True Listen Happy. | K31: Valid | L31: Valid | M31: Valid | N31: =IF(OR(B31="",C31="",D31="",F31=""),"Missing","OK") -> OK | O31: =IF(OR(Table1_17[[#This Row],[amount]]<$Y$8,Table1_17[[#This Row],[amount]]>$Y$7),"Outlier","Normal") -> Normal | P31: =IF(OR(Table1_17[[#This Row],[missing_flag]]="Missing",Table1_17[[#This Row],[outlier_flag]]="Outliers"),"Review","Valid") -> Valid
A32: TRX100030 | B32: 44814 | C32: 137108.16 | D32: Revenue | E32: Service | F32: Enterprise | G32: East | H32: CUST10325 | J32: Citizen Help Never Simple Course. | K32: Valid | L32: Valid | M32: Valid | N32: =IF(OR(B32="",C32="",D32="",F32=""),"Missing","OK") -> OK | O32: =IF(OR(Table1_17[[#This Row],[amount]]<$Y$8,Table1_17[[#This Row],[amount]]>$Y$7),"Outlier","Normal") -> Normal | P32: =IF(OR(Table1_17[[#This Row],[missing_flag]]="Missing",Table1_17[[#This Row],[outlier_flag]]="Outliers"),"Review","Valid") -> Valid
A33: TRX100031 | B33: 44624 | C33: -44326.21 | D33: Expense | E33: Other | F33: Retail | G33: East | I33: VEND1053 | J33: Billion Newspaper Modern Fine Career Somebody. | K33: Valid | L33: Valid | M33: Valid | N33: =IF(OR(B33="",C33="",D33="",F33=""),"Missing","OK") -> OK | O33: =IF(OR(Table1_17[[#This Row],[amount]]<$Y$8,Table1_17[[#This Row],[amount]]>$Y$7),"Outlier","Normal") -> Normal | P33: =IF(OR(Table1_17[[#This Row],[missing_flag]]="Missing",Table1_17[[#This Row],[outlier_flag]]="Outliers"),"Review","Valid") -> Valid
A34: TRX100032 | B34: 44970 | C34: 162088.99 | D34: Revenue | E34: Service | F34: Enterprise | G34: North | H34: CUST10203 | J34: Wall Campaign Might Anyone. | K34: Valid | L34: Valid | M34: Valid | N34: =IF(OR(B34="",C34="",D34="",F34=""),"Missing","OK") -> OK | O34: =IF(OR(Table1_17[[#This Row],[amount]]<$Y$8,Table1_17[[#This Row],[amount]]>$Y$7),"Outlier","Normal") -> Normal | P34: =IF(OR(Table1_17[[#This Row],[missing_flag]]="Missing",Table1_17[[#This Row],[outlier_flag]]="Outliers"),"Review","Valid") -> Valid
A35: TRX100033 | B35: 44847 | C35: 138103.68 | D35: Revenue | E35: Subscription | F35: Online | G35: North | H35: CUST10151 | J35: Could Impact Decide Key. | K35: Valid | L35: Valid | M35: Valid | N35: =IF(OR(B35="",C35="",D35="",F35=""),"Missing","OK") -> OK | O35: =IF(OR(Table1_17[[#This Row],[amount]]<$Y$8,Table1_17[[#This Row],[amount]]>$Y$7),"Outlier","Normal") -> Normal | P35: =IF(OR(Table1_17[[#This Row],[missing_flag]]="Missing",Table1_17[[#This Row],[outlier_flag]]="Outliers"),"Review","Valid") -> Valid
A36: TRX100034 | B36: 44695 | C36: -10197.61 | D36: Expense | E36: Utilities | F36: Retail | G36: East | I36: VEND1014 | J36: Imagine Must Who Discover Since Painting. | K36: Valid | L36: Valid | M36: Valid | N36: =IF(OR(B36="",C36="",D36="",F36=""),"Missing","OK") -> OK | O36: =IF(OR(Table1_17[[#This Row],[amount]]<$Y$8,Table1_17[[#This Row],[amount]]>$Y$7),"Outlier","Normal") -> Normal | P36: =IF(OR(Table1_17[[#This Row],[missing_flag]]="Missing",Table1_17[[#This Row],[outlier_flag]]="Outliers"),"Review","Valid") -> Valid
A37: TRX100035 | B37: 45145 | C37: -62926.94 | D37: Expense | E37: Marketing | F37: Retail | G37: West | I37: VEND1093 | J37: Training Nor Arrive. | K37: Valid | L37: Valid | M37: Valid | N37: =IF(OR(B37="",C37="",D37="",F37=""),"Missing","OK") -> OK | O37: =IF(OR(Table1_17[[#This Row],[amount]]<$Y$8,Table1_17[[#This Row],[amount]]>$Y$7),"Outlier","Normal") -> Normal | P37: =IF(OR(Table1_17[[#This Row],[missing_flag]]="Missing",Table1_17[[#This Row],[outlier_flag]]="Outliers"),"Review","Valid") -> Valid
A38: TRX100036 | B38: 45195 | C38: 144593.87 | D38: Revenue | E38: Service | F38: Enterprise | G38: East | H38: CUST10086 | J38: Field Some Arrive Society Everybody Guy Public. | K38: Valid | L38: Valid | M38: Valid | N38: =IF(OR(B38="",C38="",D38="",F38=""),"Missing","OK") -> OK | O38: =IF(OR(Table1_17[[#This Row],[amount]]<$Y$8,Table1_17[[#This Row],[amount]]>$Y$7),"Outlier","Normal") -> Normal | P38: =IF(OR(Table1_17[[#This Row],[missing_flag]]="Missing",Table1_17[[#This Row],[outlier_flag]]="Outliers"),"Review","Valid") -> Valid
A39: TRX100037 | B39: 44595 | C39: 38814.58 | D39: Revenue | E39: Product | F39: Retail | G39: North | H39: CUST10013 | J39: Order Agreement Mind Everything. | K39: Valid | L39: Valid | M39: Valid | N39: =IF(OR(B39="",C39="",D39="",F39=""),"Missing","OK") -> OK | O39: =IF(OR(Table1_17[[#This Row],[amount]]<$Y$8,Table1_17[[#This Row],[amount]]>$Y$7),"Outlier","Normal") -> Normal | P39: =IF(OR(Table1_17[[#This Row],[missing_flag]]="Missing",Table1_17[[#This Row],[outlier_flag]]="Outliers"),"Review","Valid") -> Valid
A40: TRX100038 | B40: 44983 | C40: -36977.97 | D40: Expense | E40: Rent | F40: Online | G40: East | I40: VEND1082 | J40: Watch Would Miss Interview Water Trouble. | K40: Valid | L40: Valid | M40: Valid | N40: =IF(OR(B40="",C40="",D40="",F40=""),"Missing","OK") -> OK | O40: =IF(OR(Table1_17[[#This Row],[amount]]<$Y$8,Table1_17[[#This Row],[amount]]>$Y$7),"Outlier","Normal") -> Normal | P40: =IF(OR(Table1_17[[#This Row],[missing_flag]]="Missing",Table1_17[[#This Row],[outlier_flag]]="Outliers"),"Review","Valid") -> Valid
...
